function funcionarOuNao(valor, chanceErro) {
    return new Promise((resolve, reject) => {
        if(Math.random() < chanceErro) {
            reject('Ocorreu um erro!')
        } else {
            resolve(valor)
        }
    })
}

funcionarOuNao('Testando...', 0.5)
    .then(v => console.log(`Valor: ${v}`))
    .catch(err => console.log(`Erro: ${err}`)) // depois do catch nÃ£o existe mais valor para ser tratado
    .then(() => console.log('Fim!'))